Workbook
Name _: #REF!
Name Excel_BuiltIn__FilterDatabase_1_2: #REF!
Name Excel_BuiltIn__FilterDatabase_1_3: #REF!
Name Excel_BuiltIn__FilterDatabase_1_4: #REF!
Name Excel_BuiltIn__FilterDatabase_2: #REF!
Name Excel_BuiltIn_Print_Area_1: #REF!
Name F: #REF!
Name HHHHHHHH: #REF!
Name RAJESH: #REF!
Name RAJESHR: #REF!
Name Upper: [1]Factories!$O$2:$O$18
Name Vendors: [1]Factories!$A$1:$A$20

Sheet Sheet1
A1: Container Planning | B1: PO No | C1: Customer Product Code | D1: VSN No | E1: Plant | F1: Ship Date | G1: Cancel Date | H1: Material Description | I1: Port Name | J1: Pack Inner | K1: Pack Master | L1: PO Qty | M1: Carton Qty | N1: Pallet Master | O1: Pallet Qty | P1: Total Value Item Wise | Q1: ACT CTN L | R1: ACT CTN W | S1: ACT CTN H | T1: Total CBM | U1: ACT Gr Wt | V1: ACT Net Wt | W1: Total Gross Weight | X1: Total Net Weight | Y1: Transport Mode | AB1: Pallet Qty
A2: 01 x 40 | B2: 0973268127 | C2: 672944123 | D2: DS-AC-7198 | E2: 1505 | F2: 46122 | G2: 46129 | H2: Manila Drawing Paper 18x12In 70S 65G | I2: EASTVALE-FLOW | J2: 001 | K2: 0015 | L2: =M2*K2 -> 30 | M2: 2 | N2: 0 | O2: 0 | P2: 49.7 | Q2: 47.4 | R2: 17 | S2: 32.4 | T2: =M2*Q2*R2*S2/1000000 -> 0.05221584 | U2: 10.328 | V2: 9.7 | W2: =M2*U2 -> 20.656 | X2: =V2*M2 -> 19.4 | Y2: OCEAN HEVY
B3: 0973268127 | C3: 672948712 | D3: DS-AC-7199 | E3: 1505 | F3: 46122 | G3: 46129 | H3: Manila Drawing Paper 9x12In 70S 65G | I3: EASTVALE-FLOW | J3: 001 | K3: 0026 | L3: =M3*K3 -> 104 | M3: 4 | N3: 0 | O3: 0 | P3: 91.07 | Q3: 27.4 | R3: 24.4 | S3: 32 | T3: =M3*Q3*R3*S3/1000000 -> 0.08557568 | U3: 8.808 | V3: 8.3 | W3: =M3*U3 -> 35.232 | X3: =V3*M3 -> 33.2 | Y3: OCEAN HEVY
B4: 0973268127 | C4: 675229715 | D4: CP-AC-6873 | E4: 1505 | F4: 46122 | G4: 46129 | H4: Construction Ppr 9x12in Asst HW 120S 95G | I4: EASTVALE-FLOW | J4: 001 | K4: 0008 | L4: =M4*K4 -> 17536 | M4: 2192 | N4: 0 | O4: 0 | P4: 22072.56 | Q4: 24.6 | R4: 22.3 | S4: 31.6 | T4: =M4*Q4*R4*S4/1000000 -> 37.998601 | U4: 6.974 | V4: 6.384 | W4: =M4*U4 -> 15287.008 | X4: =V4*M4 -> 13993.728 | Y4: OCEAN HEVY
B5: 0973268127 | C5: 680451997 | D5: CP-AC-7384 | E5: 1505 | F5: 46122 | G5: 46129 | H5: Heavy Constr Ppr 9x12in 240S 95G Asstort | I5: EASTVALE-FLOW | J5: 001 | K5: 0004 | L5: =M5*K5 -> 2200 | M5: 550 | N5: 0 | O5: 0 | P5: 13034.04 | Q5: 24.6 | R5: 22.4 | S5: 32.5 | T5: =M5*Q5*R5*S5/1000000 -> 9.84984 | U5: 6.96 | V5: 6.54 | W5: =M5*U5 -> 3828 | X5: =V5*M5 -> 3597 | Y5: OCEAN HEVY
L6: =SUM(L2:L5) -> 19870 | M6: =SUM(M2:M5) -> 2748 | T6: =SUM(T2:T5) -> 47.986232 | W6: =SUM(W2:W5) -> 19170.896 | X6: =SUM(X2:X5) -> 17643.328 | Z6: kh
A8: 01 x 40HC | B8: 0973268127 | C8: 680451997 | D8: CP-AC-7384 | E8: 1505 | F8: 46122 | G8: 46129 | H8: Heavy Constr Ppr 9x12in 240S 95G Asstort | I8: EASTVALE-FLOW | J8: 001 | K8: 0004 | L8: =M8*K8 -> 2952 | M8: =1288-M5 -> 738 | N8: 0 | O8: 0 | P8: 13034.04 | Q8: 24.6 | R8: 22.4 | S8: 32.5 | T8: =M8*Q8*R8*S8/1000000 -> 13.216694 | U8: 6.96 | V8: 6.54 | W8: =M8*U8 -> 5136.48 | X8: =V8*M8 -> 4826.52 | Y8: OCEAN HEVY
B9: 0973329164 | C9: 680628301 | D9: IC-VA-7700 | E9: 1505 | F9: 46122 | G9: 46129 | H9: Ruled Flash Card 3x5In 1000SH 134G Asst | I9: EASTVALE-FLOW | J9: 001 | K9: 0004 | L9: =M9*K9 -> 1940 | M9: 485 | N9: 0 | O9: 0 | P9: 5168.74 | Q9: 33.7 | R9: 19.8 | S9: 16.2 | T9: =M9*Q9*R9*S9/1000000 -> 5.2426618 | U9: 5.73 | V9: 5.36 | W9: =M9*U9 -> 2779.05 | X9: =V9*M9 -> 2599.6 | Y9: OCEAN HEVY
B10: 0973333286 | C10: 679290076 | D10: PL-VA-7758 | E10: 1505 | F10: 46122 | G10: 46129 | H10: PP Wiro 9x11in M & W Planer 15M Apr-June | I10: EASTVALE-FLOW | J10: 001 | K10: 0006 | L10: =M10*K10 -> 5898 | M10: 983 | N10: 0 | O10: 0 | P10: 15693.4 | Q10: 27.8 | R10: 13.9 | S10: 29.9 | T10: =M10*Q10*R10*S10/1000000 -> 11.357541 | U10: 5.432 | V10: 4.844 | W10: =M10*U10 -> 5339.656 | X10: =V10*M10 -> 4761.652 | Y10: OCEAN HEVY
B11: 0973334243 | C11: 578227787 | D11: FF-OP-4017 | E11: 1505 | F11: 46122 | G11: 46129 | H11: 2 Pkt Poly Portfolio W/Prong Red | I11: EASTVALE-FLOW | J11: 001 | K11: 0032 | L11: =M11*K11 -> 87360 | M11: 2730 | N11: 0 | O11: 0 | P11: 20574.27 | Q11: 25.5 | R11: 13.4 | S11: 30.4 | T11: =M11*Q11*R11*S11/1000000 -> 28.358366 | U11: 2.228 | V11: 1.85 | W11: =M11*U11 -> 6082.44 | X11: =V11*M11 -> 5050.5 | Y11: OCEAN
L12: =SUM(L8:L11) -> 98150 | M12: =SUM(M8:M11) -> 4936 | T12: =SUM(T8:T11) -> 58.175263 | W12: =SUM(W8:W11) -> 19337.626 | X12: =SUM(X8:X11) -> 17238.272 | Z12: kh
A14: 01 x 40HC | B14: 0973334243 | C14: 578227787 | D14: FF-OP-4017 | E14: 1505 | F14: 46122 | G14: 46129 | H14: 2 Pkt Poly Portfolio W/Prong Red | I14: EASTVALE-FLOW | J14: 001 | K14: 0032 | L14: =M14*K14 -> 2720 | M14: =2815-M11 -> 85 | N14: 0 | O14: 0 | P14: 20574.27 | Q14: 25.5 | R14: 13.4 | S14: 30.4 | T14: =M14*Q14*R14*S14/1000000 -> 0.8829528 | U14: 2.228 | V14: 1.85 | W14: =M14*U14 -> 189.38 | X14: =V14*M14 -> 157.25 | Y14: OCEAN
B15: 0973334243 | C15: 673195228 | D15: FF-OP-4012 | E15: 1505 | F15: 46122 | G15: 46129 | H15: 2 Pkt polyport 11¼X 9.4in w/prong Yellow | I15: EASTVALE-FLOW | J15: 001 | K15: 0032 | L15: =M15*K15 -> 96288 | M15: 3009 | N15: 0 | O15: 0 | P15: 23465.39 | Q15: 25.5 | R15: 13.4 | S15: 30.4 | T15: =M15*Q15*R15*S15/1000000 -> 31.256529 | U15: 2.228 | V15: 1.85 | W15: =M15*U15 -> 6704.052 | X15: =V15*M15 -> 5566.65 | Y15: OCEAN
B16: 0973334243 | C16: 595335499 | D16: FF-OP-3977 | E16: 1505 | F16: 46122 | G16: 46129 | H16: POLY RING BINDER 1inch 3-O Ring Black | I16: EASTVALE-FLOW | J16: 001 | K16: 0018 | L16: =M16*K16 -> 22644 | M16: 1258 | N16: 0 | O16: 0 | P16: 10207.92 | Q16: 30.4 | R16: 28 | S16: 30.5 | T16: =M16*Q16*R16*S16/1000000 -> 32.659693 | U16: 2.58 | V16: 2.05 | W16: =M16*U16 -> 3245.64 | X16: =V16*M16 -> 2578.9 | Y16: OCEAN
B17: 0973334243 | C17: 655353271 | D17: FF-OP-5669 | E17: 1505 | F17: 46122 | G17: 46129 | H17: 2 Pkt Poly Portfolio W/o Prong Red | I17: EASTVALE-FLOW | J17: 001 | K17: 0056 | L17: =M17*K17 -> 1176 | M17: 21 | N17: 0 | O17: 0 | P17: 18025.41 | Q17: 25.6 | R17: 12.4 | S17: 30.4 | T17: =M17*Q17*R17*S17/1000000 -> 0.2026537 | U17: 3.11 | V17: 2.84 | W17: =M17*U17 -> 65.31 | X17: =V17*M17 -> 59.64 | Y17: OCEAN
L18: =SUM(L14:L17) -> 122828 | M18: =SUM(M14:M17) -> 4373 | T18: =SUM(T14:T17) -> 65.001828 | W18: =SUM(W14:W17) -> 10204.382 | X18: =SUM(X14:X17) -> 8362.44 | Z18: kh
A20: 01 x 40HC | B20: 0973334243 | C20: 655353271 | D20: FF-OP-5669 | E20: 1505 | F20: 46122 | G20: 46129 | H20: 2 Pkt Poly Portfolio W/o Prong Red | I20: EASTVALE-FLOW | J20: 001 | K20: 0056 | L20: =M20*K20 -> 97216 | M20: =1757-M17 -> 1736 | N20: 0 | O20: 0 | P20: 18025.41 | Q20: 25.6 | R20: 12.4 | S20: 30.4 | T20: =M20*Q20*R20*S20/1000000 -> 16.752706 | U20: 3.11 | V20: 2.84 | W20: =M20*U20 -> 5398.96 | X20: =V20*M20 -> 4930.24 | Y20: OCEAN
B21: 0973334243 | C21: 655353273 | D21: FF-OP-5670 | E21: 1505 | F21: 46122 | G21: 46129 | H21: 2 Pkt Poly Portfolio 9.4X11.4IN YELLOW | I21: EASTVALE-FLOW | J21: 001 | K21: 0056 | L21: =M21*K21 -> 54992 | M21: 982 | N21: 0 | O21: 0 | P21: 10745.44 | Q21: 25.6 | R21: 12.4 | S21: 30.4 | T21: =M21*Q21*R21*S21/1000000 -> 9.4764728 | U21: 3.11 | V21: 2.84 | W21: =M21*U21 -> 3054.02 | X21: =V21*M21 -> 2788.88 | Y21: OCEAN
B22: 0973334243 | C22: 655353268 | D22: FF-OP-5675 | E22: 1505 | F22: 46122 | G22: 46129 | H22: 2 Pkt Poly Portfolio 9.4X11.4IN BLACK | I22: EASTVALE-FLOW | J22: 001 | K22: 0056 | L22: =M22*K22 -> 46424 | M22: 829 | N22: 0 | O22: 0 | P22: 9071.25 | Q22: 25.6 | R22: 12.4 | S22: 30.4 | T22: =M22*Q22*R22*S22/1000000 -> 7.9999959 | U22: 3.11 | V22: 2.84 | W22: =M22*U22 -> 2578.19 | X22: =V22*M22 -> 2354.36 | Y22: OCEAN
B23: 0973334243 | C23: 655369570 | D23: FF-VA-5611 | E23: 1505 | F23: 46122 | G23: 46129 | H23: Dur Poly View 1IN DSlant Ring Bind White | I23: EASTVALE-FLOW | J23: 001 | K23: 0012 | L23: =M23*K23 -> 13068 | M23: 1089 | N23: 0 | O23: 0 | P23: 25407.22 | Q23: 31.7 | R23: 28.3 | S23: 31.5 | T23: =M23*Q23*R23*S23/1000000 -> 30.774013 | U23: 4.736 | V23: 4.21 | W23: =M23*U23 -> 5157.504 | X23: =V23*M23 -> 4584.69 | Y23: OCEAN
L24: =SUM(L20:L23) -> 211700 | M24: =SUM(M20:M23) -> 4636 | T24: =SUM(T20:T23) -> 65.003187 | W24: =SUM(W20:W23) -> 16188.674 | X24: =SUM(X20:X23) -> 14658.17 | Z24: kh
A26: 01 x 40HC | B26: 0973334243 | C26: 655369570 | D26: FF-VA-5611 | E26: 1505 | F26: 46122 | G26: 46129 | H26: Dur Poly View 1IN DSlant Ring Bind White | I26: EASTVALE-FLOW | J26: 001 | K26: 0012 | L26: =M26*K26 -> 22020 | M26: =2924-M23 -> 1835 | N26: 0 | O26: 0 | P26: 25407.22 | Q26: 31.7 | R26: 28.3 | S26: 31.5 | T26: =M26*Q26*R26*S26/1000000 -> 51.855201 | U26: 4.736 | V26: 4.21 | W26: =M26*U26 -> 8690.56 | X26: =V26*M26 -> 7725.35 | Y26: OCEAN
B27: 0973334243 | C27: 665466364 | D27: FF-OP-6833 | E27: 1505 | F27: 46122 | G27: 46129 | H27: 2 Pkt Poly Portfolio W/Prong R.Royal | I27: EASTVALE-FLOW | J27: 001 | K27: 0032 | L27: =M27*K27 -> 40480 | M27: 1265 | N27: 0 | O27: 0 | P27: 19660.67 | Q27: 25.5 | R27: 13.4 | S27: 30.4 | T27: =M27*Q27*R27*S27/1000000 -> 13.140415 | U27: 2.228 | V27: 1.85 | W27: =M27*U27 -> 2818.42 | X27: =V27*M27 -> 2340.25 | Y27: OCEAN
L28: =SUM(L26:L27) -> 62500 | M28: =SUM(M26:M27) -> 3100 | T28: =SUM(T26:T27) -> 64.995616 | W28: =SUM(W26:W27) -> 11508.98 | X28: =SUM(X26:X27) -> 10065.6 | Z28: BWD
A30: 01 x 40HC | B30: 0973334243 | C30: 665466364 | D30: FF-OP-6833 | E30: 1505 | F30: 46122 | G30: 46129 | H30: 2 Pkt Poly Portfolio W/Prong R.Royal | I30: EASTVALE-FLOW | J30: 001 | K30: 0032 | L30: =M30*K30 -> 45600 | M30: =2690-M27 -> 1425 | N30: 0 | O30: 0 | P30: 19660.67 | Q30: 25.5 | R30: 13.4 | S30: 30.4 | T30: =M30*Q30*R30*S30/1000000 -> 14.802444 | U30: 2.228 | V30: 1.85 | W30: =M30*U30 -> 3174.9 | X30: =V30*M30 -> 2636.25 | Y30: OCEAN
B31: 0973334243 | C31: 665416705 | D31: FF-OP-6835 | E31: 1505 | F31: 46122 | G31: 46129 | H31: 2Pket PP Prtfolio W Prng Bright Orange | I31: EASTVALE-FLOW | J31: 001 | K31: 0032 | L31: =M31*K31 -> 29600 | M31: 925 | N31: 0 | O31: 0 | P31: 7213.52 | Q31: 25.5 | R31: 13.4 | S31: 30.4 | T31: =M31*Q31*R31*S31/1000000 -> 9.608604 | U31: 2.228 | V31: 1.85 | W31: =M31*U31 -> 2060.9 | X31: =V31*M31 -> 1711.25 | Y31: OCEAN
B32: 0973334243 | C32: 665410905 | D32: FF-OP-6836 | E32: 1505 | F32: 46122 | G32: 46129 | H32: 2Pket PP Prtfolio W Prng Purple Stardust | I32: EASTVALE-FLOW | J32: 001 | K32: 0032 | L32: =M32*K32 -> 51744 | M32: 1617 | N32: 0 | O32: 0 | P32: 12610.01 | Q32: 25.5 | R32: 13.4 | S32: 30.4 | T32: =M32*Q32*R32*S32/1000000 -> 16.796879 | U32: 2.228 | V32: 1.845 | W32: =M32*U32 -> 3602.676 | X32: =V32*M32 -> 2983.365 | Y32: OCEAN
B33: 0973334243 | C33: 673195229 | D33: FF-OP-4014 | E33: 1505 | F33: 46122 | G33: 46129 | H33: 2Pket PP Prtfolio W Prng black | I33: EASTVALE-FLOW | J33: 001 | K33: 0032 | L33: =M33*K33 -> 68960 | M33: 2155 | N33: 0 | O33: 0 | P33: 16805.55 | Q33: 25.5 | R33: 13.4 | S33: 30.4 | T33: =M33*Q33*R33*S33/1000000 -> 22.38545 | U33: 2.228 | V33: 1.845 | W33: =M33*U33 -> 4801.34 | X33: =V33*M33 -> 3975.975 | Y33: OCEAN
B34: 0973334243 | C34: 665466368 | D34: FF-OP-6834 | E34: 1505 | F34: 46122 | G34: 46129 | H34: 2 Pkt Poly Portfolio W/Prong P.Green | I34: EASTVALE-FLOW | J34: 001 | K34: 0032 | L34: =M34*K34 -> 4320 | M34: 135 | N34: 0 | O34: 0 | P34: 15998.96 | Q34: 25.5 | R34: 13.4 | S34: 30.4 | T34: =M34*Q34*R34*S34/1000000 -> 1.4023368 | U34: 2.228 | V34: 1.845 | W34: =M34*U34 -> 300.78 | X34: =V34*M34 -> 249.075 | Y34: OCEAN
L35: =SUM(L30:L34) -> 200224 | M35: =SUM(M30:M34) -> 6257 | T35: =SUM(T30:T34) -> 64.995714 | W35: =SUM(W30:W34) -> 13940.596 | X35: =SUM(X30:X34) -> 11555.915 | Z35: KH
A37: 01 x 40HC | B37: 0973334243 | C37: 665466368 | D37: FF-OP-6834 | E37: 1505 | F37: 46122 | G37: 46129 | H37: 2 Pkt Poly Portfolio W/Prong P.Green | I37: EASTVALE-FLOW | J37: 001 | K37: 0032 | L37: =M37*K37 -> 65728 | M37: =2189-M34 -> 2054 | N37: 0 | O37: 0 | P37: 15998.96 | Q37: 25.5 | R37: 13.4 | S37: 30.4 | T37: =M37*Q37*R37*S37/1000000 -> 21.336295 | U37: 2.228 | V37: 1.845 | W37: =M37*U37 -> 4576.312 | X37: =V37*M37 -> 3789.63 | Y37: OCEAN
B38: 0973334243 | C38: 665416704 | D38: FF-OP-6837 | E38: 1505 | F38: 46122 | G38: 46129 | H38: 2-Pket PP Prtfolio w/o Prng B.Orange | I38: EASTVALE-FLOW | J38: 001 | K38: 0056 | L38: =M38*K38 -> 47264 | M38: 844 | N38: 0 | O38: 0 | P38: 9235.39 | Q38: 25.6 | R38: 12.4 | S38: 30.4 | T38: =M38*Q38*R38*S38/1000000 -> 8.1447485 | U38: 3.11 | V38: 2.84 | W38: =M38*U38 -> 2624.84 | X38: =V38*M38 -> 2396.96 | Y38: OCEAN
B39: 0973334243 | C39: 665466369 | D39: FF-OP-6838 | E39: 1505 | F39: 46122 | G39: 46129 | H39: 2-Pket PP Prtfolio w/o Prng P.stardust | I39: EASTVALE-FLOW | J39: 001 | K39: 0056 | L39: =M39*K39 -> 50120 | M39: 895 | N39: 0 | O39: 0 | P39: 9793.45 | Q39: 25.6 | R39: 12.4 | S39: 30.4 | T39: =M39*Q39*R39*S39/1000000 -> 8.6369075 | U39: 3.11 | V39: 2.84 | W39: =M39*U39 -> 2783.45 | X39: =V39*M39 -> 2541.8 | Y39: OCEAN
B40: 0973334243 | C40: 665466365 | D40: FF-OP-6839 | E40: 1505 | F40: 46122 | G40: 46129 | H40: 2 Pkt Poly Portfolio W/o Prong R.Royal | I40: EASTVALE-FLOW | J40: 001 | K40: 0056 | L40: =M40*K40 -> 112168 | M40: 2003 | N40: 0 | O40: 0 | P40: 20549.18 | Q40: 25.6 | R40: 12.4 | S40: 30.4 | T40: =M40*Q40*R40*S40/1000000 -> 19.329303 | U40: 3.11 | V40: 2.84 | W40: =M40*U40 -> 6229.33 | X40: =V40*M40 -> 5688.52 | Y40: OCEAN
B41: 0973334243 | C41: 665466366 | D41: FF-OP-6840 | E41: 1505 | F41: 46122 | G41: 46129 | H41: 2 Pkt Poly Portfolio W/o Prong P.Green | I41: EASTVALE-FLOW | J41: 001 | K41: 0056 | L41: =M41*K41 -> 43848 | M41: 783 | N41: 0 | O41: 0 | P41: 14444.95 | Q41: 25.6 | R41: 12.4 | S41: 30.4 | T41: =M41*Q41*R41*S41/1000000 -> 7.5560878 | U41: 3.11 | V41: 2.84 | W41: =M41*U41 -> 2435.13 | X41: =V41*M41 -> 2223.72 | Y41: OCEAN
L42: =SUM(L37:L41) -> 319128 | M42: =SUM(M37:M41) -> 6579 | T42: =SUM(T37:T41) -> 65.003341 | W42: =SUM(W37:W41) -> 18649.062 | X42: =SUM(X37:X41) -> 16640.63 | Z42: KH
A44: 01 x 40 | B44: 0973334243 | C44: 665466366 | D44: FF-OP-6840 | E44: 1505 | F44: 46122 | G44: 46129 | H44: 2 Pkt Poly Portfolio W/o Prong P.Green | I44: EASTVALE-FLOW | J44: 001 | K44: 0056 | L44: =M44*K44 -> 35000 | M44: =1408-M41 -> 625 | N44: 0 | O44: 0 | P44: 14444.95 | Q44: 25.6 | R44: 12.4 | S44: 30.4 | T44: =M44*Q44*R44*S44/1000000 -> 6.03136 | U44: 3.11 | V44: 2.84 | W44: =M44*U44 -> 1943.75 | X44: =V44*M44 -> 1775 | Y44: OCEAN
B45: 0973334243 | C45: 665466371 | D45: FF-VA-6823 | E45: 1505 | F45: 46122 | G45: 46129 | H45: PP View 1IN DSlant Ring Binder R.Royal | I45: EASTVALE-FLOW | J45: 001 | K45: 0012 | L45: =M45*K45 -> 20808 | M45: 1734 | N45: 0 | O45: 0 | P45: 25782.43 | Q45: 31.7 | R45: 28.3 | S45: 31.5 | T45: =M45*Q45*R45*S45/1000000 -> 49.001045 | U45: 4.736 | V45: 4.21 | W45: =M45*U45 -> 8212.224 | X45: =V45*M45 -> 7300.14 | Y45: OCEAN
L46: =SUM(L44:L45) -> 55808 | M46: =SUM(M44:M45) -> 2359 | T46: =SUM(T44:T45) -> 55.032405 | W46: =SUM(W44:W45) -> 10155.974 | X46: =SUM(X44:X45) -> 9075.14 | Z46: BWD
A48: 01 x 40 | B48: 0973334243 | C48: 665466371 | D48: FF-VA-6823 | E48: 1505 | F48: 46122 | G48: 46129 | H48: PP View 1IN DSlant Ring Binder R.Royal | I48: EASTVALE-FLOW | J48: 001 | K48: 0012 | L48: =M48*K48 -> 13152 | M48: =2830-M45 -> 1096 | N48: 0 | O48: 0 | P48: 25782.43 | Q48: 31.7 | R48: 28.3 | S48: 31.5 | T48: =M48*Q48*R48*S48/1000000 -> 30.971826 | U48: 4.736 | V48: 4.21 | W48: =M48*U48 -> 5190.656 | X48: =V48*M48 -> 4614.16 | Y48: OCEAN
...

Sheet CLR format
A1: CONTAINER MANIFEST (CLR)
A2: Blue color column = Mandatory
A3: DO Required Date: | B3: =N6-2 -> 46120
A4: Cargo Details
A5: Carrier Booking no | B5: Container Number | C5: Line_Seal_NO/ Carrier | D5: Cable_Seal_No/ WMT_seal | E5: Container_SIZE | F5: Sub_case(YES/NO) | G5: SHIPPER_Name | H5: SO_Number | I5: PO_Number | J5: SKU/ITEM_NO | K5: Cartons | L5: Grs_Wt | M5: CBM | N5: STUFFING_DATE | O5: Cargo_name | P5: INVOICE_NO. | Q5: INVOICE_DATE | R5: SB_NO | S5: SB_Date | T5: HS CODE | U5: DC_CODE | V5: NCM_code for BR | W5: LC_NO | X5: SKU LOT CODE | Y5: EXPIRY DATE | Z5: Additional remarks
E6: 40'hc | F6: YES | G6: NAVNEET EDUCATION LTD | I6: =Sheet1!B2 -> 0973268127 | J6: =Sheet1!C2 -> 672944123 | K6: =Sheet1!M2 -> 2 | L6: =Sheet1!W2 -> 20.656 | M6: =Sheet1!T2 -> 0.05221584 | N6: =Sheet1!F2 -> 46122
E7: 40'hc | F7: YES | G7: NAVNEET EDUCATION LTD | I7: =Sheet1!B3 -> 0973268127 | J7: =Sheet1!C3 -> 672948712 | K7: =Sheet1!M3 -> 4 | L7: =Sheet1!W3 -> 35.232 | M7: =Sheet1!T3 -> 0.08557568 | N7: =Sheet1!F3 -> 46122
E8: 40'hc | F8: YES | G8: NAVNEET EDUCATION LTD | I8: =Sheet1!B4 -> 0973268127 | J8: =Sheet1!C4 -> 675229715 | K8: =Sheet1!M4 -> 2192 | L8: =Sheet1!W4 -> 15287.008 | M8: =Sheet1!T4 -> 37.998601 | N8: =Sheet1!F4 -> 46122
E9: 40'hc | F9: YES | G9: NAVNEET EDUCATION LTD | I9: =Sheet1!B5 -> 0973268127 | J9: =Sheet1!C5 -> 680451997 | K9: =Sheet1!M5 -> 550 | L9: =Sheet1!W5 -> 3828 | M9: =Sheet1!T5 -> 9.84984 | N9: =Sheet1!F5 -> 46122
E10: 40'hc | F10: YES | G10: NAVNEET EDUCATION LTD | K10: =Sheet1!M6 -> 2748 | L10: =Sheet1!W6 -> 19170.896 | M10: =Sheet1!T6 -> 47.986232
E11: 40'hc | F11: YES | G11: NAVNEET EDUCATION LTD
E12: 40'hc | F12: YES | G12: NAVNEET EDUCATION LTD | I12: =Sheet1!B8 -> 0973268127 | J12: =Sheet1!C8 -> 680451997 | K12: =Sheet1!M8 -> 738 | L12: =Sheet1!W8 -> 5136.48 | M12: =Sheet1!T8 -> 13.216694 | N12: =Sheet1!F8 -> 46122
E13: 40'hc | F13: YES | G13: NAVNEET EDUCATION LTD | I13: =Sheet1!B9 -> 0973329164 | J13: =Sheet1!C9 -> 680628301 | K13: =Sheet1!M9 -> 485 | L13: =Sheet1!W9 -> 2779.05 | M13: =Sheet1!T9 -> 5.2426618 | N13: =Sheet1!F9 -> 46122
E14: 40'hc | F14: YES | G14: NAVNEET EDUCATION LTD | I14: =Sheet1!B10 -> 0973333286 | J14: =Sheet1!C10 -> 679290076 | K14: =Sheet1!M10 -> 983 | L14: =Sheet1!W10 -> 5339.656 | M14: =Sheet1!T10 -> 11.357541 | N14: =Sheet1!F10 -> 46122
E15: 40'hc | F15: YES | G15: NAVNEET EDUCATION LTD | I15: =Sheet1!B11 -> 0973334243 | J15: =Sheet1!C11 -> 578227787 | K15: =Sheet1!M11 -> 2730 | L15: =Sheet1!W11 -> 6082.44 | M15: =Sheet1!T11 -> 28.358366 | N15: =Sheet1!F11 -> 46122
E16: 40'hc | F16: YES | G16: NAVNEET EDUCATION LTD | K16: =Sheet1!M12 -> 4936 | L16: =Sheet1!W12 -> 19337.626 | M16: =Sheet1!T12 -> 58.175263
E17: 40'hc | F17: YES | G17: NAVNEET EDUCATION LTD
E18: 40'hc | F18: YES | G18: NAVNEET EDUCATION LTD | I18: =Sheet1!B14 -> 0973334243 | J18: =Sheet1!C14 -> 578227787 | K18: =Sheet1!M14 -> 85 | L18: =Sheet1!W14 -> 189.38 | M18: =Sheet1!T14 -> 0.8829528 | N18: =Sheet1!F14 -> 46122
E19: 40'hc | F19: YES | G19: NAVNEET EDUCATION LTD | I19: =Sheet1!B15 -> 0973334243 | J19: =Sheet1!C15 -> 673195228 | K19: =Sheet1!M15 -> 3009 | L19: =Sheet1!W15 -> 6704.052 | M19: =Sheet1!T15 -> 31.256529 | N19: =Sheet1!F15 -> 46122
E20: 40'hc | F20: YES | G20: NAVNEET EDUCATION LTD | I20: =Sheet1!B16 -> 0973334243 | J20: =Sheet1!C16 -> 595335499 | K20: =Sheet1!M16 -> 1258 | L20: =Sheet1!W16 -> 3245.64 | M20: =Sheet1!T16 -> 32.659693 | N20: =Sheet1!F16 -> 46122
E21: 40'hc | F21: YES | G21: NAVNEET EDUCATION LTD | I21: =Sheet1!B17 -> 0973334243 | J21: =Sheet1!C17 -> 655353271 | K21: =Sheet1!M17 -> 21 | L21: =Sheet1!W17 -> 65.31 | M21: =Sheet1!T17 -> 0.2026537 | N21: =Sheet1!F17 -> 46122
E22: 40'hc | F22: YES | G22: NAVNEET EDUCATION LTD | K22: =Sheet1!M18 -> 4373 | L22: =Sheet1!W18 -> 10204.382 | M22: =Sheet1!T18 -> 65.001828
E23: 40'hc | F23: YES | G23: NAVNEET EDUCATION LTD
E24: 40'hc | F24: YES | G24: NAVNEET EDUCATION LTD | I24: =Sheet1!B20 -> 0973334243 | J24: =Sheet1!C20 -> 655353271 | K24: =Sheet1!M20 -> 1736 | L24: =Sheet1!W20 -> 5398.96 | M24: =Sheet1!T20 -> 16.752706 | N24: =Sheet1!F20 -> 46122
E25: 40'hc | F25: YES | G25: NAVNEET EDUCATION LTD | I25: =Sheet1!B21 -> 0973334243 | J25: =Sheet1!C21 -> 655353273 | K25: =Sheet1!M21 -> 982 | L25: =Sheet1!W21 -> 3054.02 | M25: =Sheet1!T21 -> 9.4764728 | N25: =Sheet1!F21 -> 46122
E26: 40'hc | F26: YES | G26: NAVNEET EDUCATION LTD | I26: =Sheet1!B22 -> 0973334243 | J26: =Sheet1!C22 -> 655353268 | K26: =Sheet1!M22 -> 829 | L26: =Sheet1!W22 -> 2578.19 | M26: =Sheet1!T22 -> 7.9999959 | N26: =Sheet1!F22 -> 46122
E27: 40'hc | F27: YES | G27: NAVNEET EDUCATION LTD | I27: =Sheet1!B23 -> 0973334243 | J27: =Sheet1!C23 -> 655369570 | K27: =Sheet1!M23 -> 1089 | L27: =Sheet1!W23 -> 5157.504 | M27: =Sheet1!T23 -> 30.774013 | N27: =Sheet1!F23 -> 46122
E28: 40'hc | F28: YES | G28: NAVNEET EDUCATION LTD | K28: =Sheet1!M24 -> 4636 | L28: =Sheet1!W24 -> 16188.674 | M28: =Sheet1!T24 -> 65.003187
E29: 40'hc | F29: YES | G29: NAVNEET EDUCATION LTD
E30: 40'hc | F30: YES | G30: NAVNEET EDUCATION LTD | I30: =Sheet1!B26 -> 0973334243 | J30: =Sheet1!C26 -> 655369570 | K30: =Sheet1!M26 -> 1835 | L30: =Sheet1!W26 -> 8690.56 | M30: =Sheet1!T26 -> 51.855201 | N30: =Sheet1!F26 -> 46122
E31: 40'hc | F31: YES | G31: NAVNEET EDUCATION LTD | I31: =Sheet1!B27 -> 0973334243 | J31: =Sheet1!C27 -> 665466364 | K31: =Sheet1!M27 -> 1265 | L31: =Sheet1!W27 -> 2818.42 | M31: =Sheet1!T27 -> 13.140415 | N31: =Sheet1!F27 -> 46122
E32: 40'hc | F32: YES | G32: NAVNEET EDUCATION LTD | K32: =Sheet1!M28 -> 3100 | L32: =Sheet1!W28 -> 11508.98 | M32: =Sheet1!T28 -> 64.995616
E33: 40'hc | F33: YES | G33: NAVNEET EDUCATION LTD
E34: 40'hc | F34: YES | G34: NAVNEET EDUCATION LTD | I34: =Sheet1!B30 -> 0973334243 | J34: =Sheet1!C30 -> 665466364 | K34: =Sheet1!M30 -> 1425 | L34: =Sheet1!W30 -> 3174.9 | M34: =Sheet1!T30 -> 14.802444 | N34: =Sheet1!F30 -> 46122
E35: 40'hc | F35: YES | G35: NAVNEET EDUCATION LTD | I35: =Sheet1!B31 -> 0973334243 | J35: =Sheet1!C31 -> 665416705 | K35: =Sheet1!M31 -> 925 | L35: =Sheet1!W31 -> 2060.9 | M35: =Sheet1!T31 -> 9.608604 | N35: =Sheet1!F31 -> 46122
E36: 40'hc | F36: YES | G36: NAVNEET EDUCATION LTD | I36: =Sheet1!B32 -> 0973334243 | J36: =Sheet1!C32 -> 665410905 | K36: =Sheet1!M32 -> 1617 | L36: =Sheet1!W32 -> 3602.676 | M36: =Sheet1!T32 -> 16.796879 | N36: =Sheet1!F32 -> 46122
E37: 40'hc | F37: YES | G37: NAVNEET EDUCATION LTD | I37: =Sheet1!B33 -> 0973334243 | J37: =Sheet1!C33 -> 673195229 | K37: =Sheet1!M33 -> 2155 | L37: =Sheet1!W33 -> 4801.34 | M37: =Sheet1!T33 -> 22.38545 | N37: =Sheet1!F33 -> 46122
E38: 40'hc | F38: YES | G38: NAVNEET EDUCATION LTD | I38: =Sheet1!B34 -> 0973334243 | J38: =Sheet1!C34 -> 665466368 | K38: =Sheet1!M34 -> 135 | L38: =Sheet1!W34 -> 300.78 | M38: =Sheet1!T34 -> 1.4023368 | N38: =Sheet1!F34 -> 46122
E39: 40'hc | F39: YES | G39: NAVNEET EDUCATION LTD | K39: =Sheet1!M35 -> 6257 | L39: =Sheet1!W35 -> 13940.596 | M39: =Sheet1!T35 -> 64.995714
E40: 40'hc | F40: YES | G40: NAVNEET EDUCATION LTD
...

Sheet S-sheet
A1: ** Format to be used for Slip sheets
A4: Supplier | B4: PO Number | C4: Item No | D4: Carton Dimension | G4: Carton cube | H4: Number of cartons | I4: Cube (cbm) | J4: Slip sheet Dimension | M4: Slip sheet cube (cbm) | N4: Total number of Slip Sheets | O4: Cube usage of this item (as per WMGL) | P4: Equipment Size | Q4: ETD
D5: L (cm) | E5: W (cm) | F5: H (cm) | J5: L (cm) | K5: W (cm) | L5: H (cm)
A6: NAVNEET EDUCATION LTD | B6: 2027881837 | C6: 574663392 | D6: 34.4 | E6: 26.6 | F6: 25.9 | G6: =D6*E6*F6/1000000 -> 0.023699536 | H6: 2640 | I6: =G6*H6 -> 62.566775 | J6: =R6/10 -> 107.95 | K6: =S6/10 -> 96.52 | L6: =T6/10 -> 128.27 | M6: =J6*K6*L6/1000000 -> 1.336488 | N6: 48 | O6: =M6*N6 -> 64.151423 | P6: 01 x 40'HC | Q6: 44791 | R6: 1079.5 | S6: 965.2 | T6: 1282.7
A10: NAVNEET EDUCATION LTD | B10: 2027881837 | C10: 556928859 | D10: 25.7 | E10: 17.5 | F10: 30.1 | G10: =D10*E10*F10/1000000 -> 0.013537475 | H10: 3080 | I10: =G10*H10 -> 41.695423 | J10: =R10/10 -> 109.2 | K10: =S10/10 -> 91.5 | L10: =T10/10 -> 124 | M10: =J10*K10*L10/1000000 -> 1.2389832 | N10: 35 | O10: =M10*N10 -> 43.364412 | P10: 01 x 40'HC | Q10: 44791 | R10: 1092 | S10: 915 | T10: 1240
A11: NAVNEET EDUCATION LTD | B11: 2027881837 | C11: 578112065 | D11: 25.5 | E11: 12.5 | F11: 30.2 | G11: =D11*E11*F11/1000000 -> 0.00962625 | H11: 128 | I11: =G11*H11 -> 1.23216 | J11: =R11/10 -> 115 | K11: =S11/10 -> 95 | L11: =T11/10 -> 124 | M11: =J11*K11*L11/1000000 -> 1.3547 | N11: 1 | O11: =M11*N11 -> 1.3547 | R11: 1150 | S11: 950 | T11: 1240
A12: NAVNEET EDUCATION LTD | B12: 2027881837 | C12: 572522682 | D12: 34.5 | E12: 32 | F12: 25.5 | G12: =D12*E12*F12/1000000 -> 0.028152 | H12: 540 | I12: =G12*H12 -> 15.20208 | J12: =R12/10 -> 104.14 | K12: =S12/10 -> 96.52 | L12: =T12/10 -> 128.27 | M12: =J12*K12*L12/1000000 -> 1.2893178 | N12: 12 | O12: =M12*N12 -> 15.471814 | R12: 1041.4 | S12: 965.2 | T12: 1282.7
A16: NAVNEET EDUCATION LTD | B16: 2027881837 | C16: 572522682 | D16: 34.5 | E16: 32 | F16: 25.5 | G16: =D16*E16*F16/1000000 -> 0.028152 | H16: 1305 | I16: =G16*H16 -> 36.73836 | J16: =R16/10 -> 104.14 | K16: =S16/10 -> 96.52 | L16: =T16/10 -> 128.27 | M16: =J16*K16*L16/1000000 -> 1.2893178 | N16: 29 | O16: =M16*N16 -> 37.390216 | P16: 01 x 40'HC | Q16: 44791 | R16: 1041.4 | S16: 965.2 | T16: 1282.7
A17: NAVNEET EDUCATION LTD | B17: 2027881837 | C17: 577088561 | D17: 34.3 | E17: 31.8 | F17: 25.9 | G17: =D17*E17*F17/1000000 -> 0.028250166 | H17: 855 | I17: =G17*H17 -> 24.153892 | J17: =R17/10 -> 104.14 | K17: =S17/10 -> 97.79 | L17: =T17/10 -> 128.27 | M17: =J17*K17*L17/1000000 -> 1.3062825 | N17: 19 | O17: =M17*N17 -> 24.819368 | R17: 1041.4 | S17: 977.9 | T17: 1282.7
A20: NAVNEET EDUCATION LTD | B20: 2027881837 | C20: 579037110 | D20: 26.1 | E20: 18.7 | F20: 31.2 | G20: =D20*E20*F20/1000000 -> 0.015227784 | H20: 528 | I20: =G20*H20 -> 8.04027 | J20: =R20/10 -> 105 | K20: =S20/10 -> 96 | L20: =T20/10 -> 95 | M20: =J20*K20*L20/1000000 -> 0.9576 | N20: 8 | O20: =M20*N20 -> 7.6608 | P20: 01 x 40'HC | Q20: 44791 | R20: 1050 | S20: 960 | T20: 950
A21: NAVNEET EDUCATION LTD | B21: 2027881837 | C21: 576345787 | D21: 20.1 | E21: 17.4 | F21: 22.5 | G21: =D21*E21*F21/1000000 -> 0.00786915 | H21: 3100 | I21: =G21*H21 -> 24.394365 | J21: =R21/10 -> 105 | K21: =S21/10 -> 90 | L21: =T21/10 -> 94 | M21: =J21*K21*L21/1000000 -> 0.8883 | N21: 31 | O21: =M21*N21 -> 27.5373 | R21: 1050 | S21: 900 | T21: 940
A22: NAVNEET EDUCATION LTD | B22: 2027881837 | C22: 564988471 | D22: 28.5 | E22: 19 | F22: 29.5 | G22: =D22*E22*F22/1000000 -> 0.01597425 | H22: 540 | I22: =G22*H22 -> 8.626095 | J22: =R22/10 -> 112 | K22: =S22/10 -> 95 | L22: =T22/10 -> 90 | M22: =J22*K22*L22/1000000 -> 0.9576 | N22: 9 | O22: =M22*N22 -> 8.6184 | R22: 1120 | S22: 950 | T22: 900
A25: NAVNEET EDUCATION LTD | B25: 2027881837 | C25: 595466280 | D25: 23 | E25: 22 | F25: 29 | G25: =D25*E25*F25/1000000 -> 0.014674 | H25: 1140 | I25: =G25*H25 -> 16.72836 | J25: =R25/10 -> 110 | K25: =S25/10 -> 92 | L25: =T25/10 -> 87 | M25: =J25*K25*L25/1000000 -> 0.88044 | N25: 19 | O25: =M25*N25 -> 16.72836 | P25: 01 x 40'HC | Q25: 44791 | R25: 1100 | S25: 920 | T25: 870
A26: NAVNEET EDUCATION LTD | B26: 2027881837 | C26: 595487226 | D26: 33.5 | E26: 27.5 | F26: 8 | G26: =D26*E26*F26/1000000 -> 0.00737 | H26: 924 | I26: =G26*H26 -> 6.80988 | J26: =R26/10 -> 109.22 | K26: =S26/10 -> 96.52 | L26: =T26/10 -> 111.76 | M26: =J26*K26*L26/1000000 -> 1.1781644 | N26: 6 | O26: =M26*N26 -> 7.0689861 | R26: 1092.2 | S26: 965.2 | T26: 1117.6
A27: NAVNEET EDUCATION LTD | B27: 2027882264 | C27: 574663392 | D27: 34.4 | E27: 26.6 | F27: 25.9 | G27: =D27*E27*F27/1000000 -> 0.023699536 | H27: 1265 | I27: =G27*H27 -> 29.979913 | J27: =R27/10 -> 107.95 | K27: =S27/10 -> 96.52 | L27: =T27/10 -> 128.27 | M27: =J27*K27*L27/1000000 -> 1.336488 | N27: 23 | O27: =M27*N27 -> 30.739223 | R27: 1079.5 | S27: 965.2 | T27: 1282.7
F31: Total | H31: =SUM(H6:H30) -> 16045 | I31: =SUM(I6:I30) -> 276.16757 | L31: Total | M31: =SUM(M6:M30) -> 14.013682 | N31: =SUM(N6:N30) -> 240 | O31: =SUM(O6:O30) -> 284.905
